Workbook
Name Dati_colture: Sintesi!$D$9:$F$25
Name HI: 'Paste cellparameters here'!$B$3:$E$3
Name ii0: 'Paste cellparameters here'!$B$14:$E$14
Name iid: 'Paste cellparameters here'!$B$16:$E$16
Name iie: 'Paste cellparameters here'!$B$15:$E$15
Name irandom: 'Paste cellparameters here'!$B$18
Name Kcbini: 'Paste cellparameters here'!$B$12:$E$12
Name Kcbmax: 'Paste cellparameters here'!$B$13:$E$13
Name Kcbmin: 'Paste cellparameters here'!$B$11:$E$11
Name KyP: 'Paste cellparameters here'!$B$5:$E$8
Name KyT: 'Paste cellparameters here'!$B$4:$E$4
Name Tcrit: 'Paste cellparameters here'!$B$9:$E$9
Name Tlim: 'Paste cellparameters here'!$B$10:$E$10
Name WPadj: 'Paste cellparameters here'!$B$2:$E$2

Sheet Sintesi
B2: Parametri di simulazione
B3: Codice uso suolo | C3: ='Paste cellinfo here'!B4
B4: Anno | C4: ='Paste cellinfo here'!B25
B5: Spessore primo strato | C5: ='Paste cellinfo here'!B23
B6: Spessore massimo secondo strato | C6: ='Paste cellinfo here'!B24
B8: Dati delle colture | C8: =IF(C9="","","Prima coltura") | D8: =IF(D9="","","Seconda coltura") | E8: =IF(E9="","","Terza coltura") | F8: =IF(F9="","","Quarta coltura")
B9: Data di emergenza (DOI) | C9: {=IF(ISNUMBER(ii0),ii0+irandom,"")}
B10: Data di raccolta (DOI) | C10: {=IF(ISNUMBER(iie),iie+irandom,"")}
B11: Durata ciclo colturale | C11: {=IF(ISTEXT(_xlfn.ANCHORARRAY(C9)),"",IF(_xlfn.ANCHORARRAY(C10)-_xlfn.ANCHORARRAY(C9)<0,_xlfn.ANCHORARRAY(C10)-_xlfn.ANCHORARRAY(C9)+366,_xlfn.ANCHORARRAY(C10)-_xlfn.ANCHORARRAY(C9)+1))}
B12: Data di emergenza | C12: {=IF(ISTEXT(_xlfn.ANCHORARRAY(C9)),"",DATE($C$4-1,12,31)+_xlfn.ANCHORARRAY(C9))}
B13: Data di raccolta | C13: {=IF(ISTEXT(_xlfn.ANCHORARRAY(C10)),"",DATE($C$4-1,12,31)+_xlfn.ANCHORARRAY(C10))}
B14: Kcb minimo | C14: {=IF(Kcbmin="","",Kcbmin)}
B15: Kcb ini | C15: {=IF(Kcbini="","",Kcbini)}
B16: Kcb massimo | C16: {=IF(Kcbmax="","",Kcbmax)}
B17: Tcrit | C17: {=IF(Tcrit="","",Tcrit)}
B18: Tlim | C18: {=IF(Tlim="","",Tlim)}
B19: KyT | C19: {=IF(KyT="","",KyT)}
B20: Ky1 | C20: {=IF(KyP="","",KyP)}
B21: Ky2 | C21: 0.9
B22: Ky3 | C22: 1.5
B23: Ky4 | C23: 0.5
B24: WPadj | C24: {=IF(WPadj="","",WPadj)}
B25: HI | C25: {=IF(HI="","",HI)}
B27: Caratteristiche idrauliche del suolo | C27: m3/m3 | D27: mm
B28: Theta I sat | C28: ='Paste cellinfo here'!B11 | D28: =C28*$C$5*1000 | F28: mm | G28: TAW
B29: Theta I fc | C29: ='Paste cellinfo here'!B12 | D29: =C29*$C$5*1000 | F29: 1° strato | G29: =D29-D30
B30: Theta I wp | C30: ='Paste cellinfo here'!B13 | D30: =C30*$C$5*1000 | F30: 2° strato | G30: =D33-D34
B31: Theta I r | C31: ='Paste cellinfo here'!B14 | D31: =C31*$C$5*1000 | F31: intero profilo | G31: =G29+G30
B32: Theta II sat | C32: ='Paste cellinfo here'!B15 | D32: =C32*$C$6*1000
B33: Theta II fc | C33: ='Paste cellinfo here'!B16 | D33: =C33*$C$6*1000
B34: Theta II wp | C34: ='Paste cellinfo here'!B17 | D34: =C34*$C$6*1000
B35: Theta II r | C35: ='Paste cellinfo here'!B18 | D35: =C35*$C$6*1000
B36: AWC | D36: =D33-D34
B38: Dati relativi al bilancio idrologico - 1° strato | C38: Anno intero | D38: =IF(C9="","","Prima coltura") | E38: =IF(D9="","","Prima coltura") | F38: =IF(E9="","","Prima coltura") | G38: =IF(F9="","","Prima coltura")
B39: Precipitazioni [mm] | C39: =SUM('Paste cell here'!B2:B366) | D39: =IF(ISTEXT(C9),"",IF(C9<C10,SUM(INDIRECT(ADDRESS(C9+1,2,,,"Paste cell here")):INDIRECT(ADDRESS(C10+1,2,,,"Paste cell here"))),SUM('Paste cell here'!B2:INDIRECT(ADDRESS(C10+1,2,,,"Paste cell here")))+SUM(INDIRECT(ADDRESS(C9+1,2,,,"Paste cell here")):'Paste cell here'!B366))) | E39: =IF(ISTEXT(D9),"",IF(D9<D10,SUM(INDIRECT(ADDRESS(D9+1,2,,,"Paste cell here")):INDIRECT(ADDRESS(D10+1,2,,,"Paste cell here"))),SUM('Paste cell here'!C2:INDIRECT(ADDRESS(D10+1,2,,,"Paste cell here")))+SUM(INDIRECT(ADDRESS(D9+1,2,,,"Paste cell here")):'Paste cell here'!C366))) | F39: =IF(ISTEXT(E9),"",IF(E9<E10,SUM(INDIRECT(ADDRESS(E9+1,2,,,"Paste cell here")):INDIRECT(ADDRESS(E10+1,2,,,"Paste cell here"))),SUM('Paste cell here'!D2:INDIRECT(ADDRESS(E10+1,2,,,"Paste cell here")))+SUM(INDIRECT(ADDRESS(E9+1,2,,,"Paste cell here")):'Paste cell here'!D366))) | G39: =IF(ISTEXT(F9),"",IF(F9<F10,SUM(INDIRECT(ADDRESS(F9+1,2,,,"Paste cell here")):INDIRECT(ADDRESS(F10+1,2,,,"Paste cell here"))),SUM('Paste cell here'!E2:INDIRECT(ADDRESS(F10+1,2,,,"Paste cell here")))+SUM(INDIRECT(ADDRESS(F9+1,2,,,"Paste cell here")):'Paste cell here'!E366)))
B40: Irrigazione [mm] | C40: =SUM('Paste cell here'!I2:I366) | D40: =IF(ISTEXT(C9),"",IF(C9<C10,SUM(INDIRECT(ADDRESS(C9+1,9,,,"Paste cell here")):INDIRECT(ADDRESS(C10+1,9,,,"Paste cell here"))),SUM('Paste cell here'!I2:INDIRECT(ADDRESS(C10+1,9,,,"Paste cell here")))+SUM(INDIRECT(ADDRESS(C9+1,9,,,"Paste cell here")):'Paste cell here'!I366))) | E40: =IF(ISTEXT(D9),"",IF(D9<D10,SUM(INDIRECT(ADDRESS(D9+1,9,,,"Paste cell here")):INDIRECT(ADDRESS(D10+1,9,,,"Paste cell here"))),SUM('Paste cell here'!J2:INDIRECT(ADDRESS(D10+1,9,,,"Paste cell here")))+SUM(INDIRECT(ADDRESS(D9+1,9,,,"Paste cell here")):'Paste cell here'!J366))) | F40: =IF(ISTEXT(E9),"",IF(E9<E10,SUM(INDIRECT(ADDRESS(E9+1,9,,,"Paste cell here")):INDIRECT(ADDRESS(E10+1,9,,,"Paste cell here"))),SUM('Paste cell here'!K2:INDIRECT(ADDRESS(E10+1,9,,,"Paste cell here")))+SUM(INDIRECT(ADDRESS(E9+1,9,,,"Paste cell here")):'Paste cell here'!K366))) | G40: =IF(ISTEXT(F9),"",IF(F9<F10,SUM(INDIRECT(ADDRESS(F9+1,9,,,"Paste cell here")):INDIRECT(ADDRESS(F10+1,9,,,"Paste cell here"))),SUM('Paste cell here'!L2:INDIRECT(ADDRESS(F10+1,9,,,"Paste cell here")))+SUM(INDIRECT(ADDRESS(F9+1,9,,,"Paste cell here")):'Paste cell here'!L366)))
B41: Intercezione [mm] | C41: =SUM('Paste cell here'!M2:M366) | D41: =IF(ISTEXT(C9),"",IF(C9<C10,SUM(INDIRECT(ADDRESS(C9+1,13,,,"Paste cell here")):INDIRECT(ADDRESS(C10+1,13,,,"Paste cell here"))),SUM('Paste cell here'!M2:INDIRECT(ADDRESS(C10+1,13,,,"Paste cell here")))+SUM(INDIRECT(ADDRESS(C9+1,13,,,"Paste cell here")):'Paste cell here'!M366))) | E41: =IF(ISTEXT(D9),"",IF(D9<D10,SUM(INDIRECT(ADDRESS(D9+1,13,,,"Paste cell here")):INDIRECT(ADDRESS(D10+1,13,,,"Paste cell here"))),SUM('Paste cell here'!N2:INDIRECT(ADDRESS(D10+1,13,,,"Paste cell here")))+SUM(INDIRECT(ADDRESS(D9+1,13,,,"Paste cell here")):'Paste cell here'!N366))) | F41: =IF(ISTEXT(E9),"",IF(E9<E10,SUM(INDIRECT(ADDRESS(E9+1,13,,,"Paste cell here")):INDIRECT(ADDRESS(E10+1,13,,,"Paste cell here"))),SUM('Paste cell here'!O2:INDIRECT(ADDRESS(E10+1,13,,,"Paste cell here")))+SUM(INDIRECT(ADDRESS(E9+1,13,,,"Paste cell here")):'Paste cell here'!O366))) | G41: =IF(ISTEXT(F9),"",IF(F9<F10,SUM(INDIRECT(ADDRESS(F9+1,13,,,"Paste cell here")):INDIRECT(ADDRESS(F10+1,13,,,"Paste cell here"))),SUM('Paste cell here'!P2:INDIRECT(ADDRESS(F10+1,13,,,"Paste cell here")))+SUM(INDIRECT(ADDRESS(F9+1,13,,,"Paste cell here")):'Paste cell here'!P366)))
B42: Scorrimento [mm] | C42: =SUM('Paste cell here'!N2:N366) | D42: =IF(ISTEXT(C9),"",IF(C9<C10,SUM(INDIRECT(ADDRESS(C9+1,14,,,"Paste cell here")):INDIRECT(ADDRESS(C10+1,14,,,"Paste cell here"))),SUM('Paste cell here'!N2:INDIRECT(ADDRESS(C10+1,14,,,"Paste cell here")))+SUM(INDIRECT(ADDRESS(C9+1,14,,,"Paste cell here")):'Paste cell here'!N366))) | E42: =IF(ISTEXT(D9),"",IF(D9<D10,SUM(INDIRECT(ADDRESS(D9+1,14,,,"Paste cell here")):INDIRECT(ADDRESS(D10+1,14,,,"Paste cell here"))),SUM('Paste cell here'!O2:INDIRECT(ADDRESS(D10+1,14,,,"Paste cell here")))+SUM(INDIRECT(ADDRESS(D9+1,14,,,"Paste cell here")):'Paste cell here'!O366))) | F42: =IF(ISTEXT(E9),"",IF(E9<E10,SUM(INDIRECT(ADDRESS(E9+1,14,,,"Paste cell here")):INDIRECT(ADDRESS(E10+1,14,,,"Paste cell here"))),SUM('Paste cell here'!P2:INDIRECT(ADDRESS(E10+1,14,,,"Paste cell here")))+SUM(INDIRECT(ADDRESS(E9+1,14,,,"Paste cell here")):'Paste cell here'!P366))) | G42: =IF(ISTEXT(F9),"",IF(F9<F10,SUM(INDIRECT(ADDRESS(F9+1,14,,,"Paste cell here")):INDIRECT(ADDRESS(F10+1,14,,,"Paste cell here"))),SUM('Paste cell here'!Q2:INDIRECT(ADDRESS(F10+1,14,,,"Paste cell here")))+SUM(INDIRECT(ADDRESS(F9+1,14,,,"Paste cell here")):'Paste cell here'!Q366)))
B43: Infiltrazione [mm] | C43: =SUM('Paste cell here'!O2:O366) | D43: =IF(ISTEXT(C9),"",IF(C9<C10,SUM(INDIRECT(ADDRESS(C9+1,15,,,"Paste cell here")):INDIRECT(ADDRESS(C10+1,15,,,"Paste cell here"))),SUM('Paste cell here'!O2:INDIRECT(ADDRESS(C10+1,15,,,"Paste cell here")))+SUM(INDIRECT(ADDRESS(C9+1,15,,,"Paste cell here")):'Paste cell here'!O366))) | E43: =IF(ISTEXT(D9),"",IF(D9<D10,SUM(INDIRECT(ADDRESS(D9+1,15,,,"Paste cell here")):INDIRECT(ADDRESS(D10+1,15,,,"Paste cell here"))),SUM('Paste cell here'!P2:INDIRECT(ADDRESS(D10+1,15,,,"Paste cell here")))+SUM(INDIRECT(ADDRESS(D9+1,15,,,"Paste cell here")):'Paste cell here'!P366))) | F43: =IF(ISTEXT(E9),"",IF(E9<E10,SUM(INDIRECT(ADDRESS(E9+1,15,,,"Paste cell here")):INDIRECT(ADDRESS(E10+1,15,,,"Paste cell here"))),SUM('Paste cell here'!Q2:INDIRECT(ADDRESS(E10+1,15,,,"Paste cell here")))+SUM(INDIRECT(ADDRESS(E9+1,15,,,"Paste cell here")):'Paste cell here'!Q366))) | G43: =IF(ISTEXT(F9),"",IF(F9<F10,SUM(INDIRECT(ADDRESS(F9+1,15,,,"Paste cell here")):INDIRECT(ADDRESS(F10+1,15,,,"Paste cell here"))),SUM('Paste cell here'!R2:INDIRECT(ADDRESS(F10+1,15,,,"Paste cell here")))+SUM(INDIRECT(ADDRESS(F9+1,15,,,"Paste cell here")):'Paste cell here'!R366)))
B44: Evaporazione [mm] | C44: =SUM('Paste cell here'!Q2:Q366) | D44: =IF(ISTEXT(C9),"",IF(C9<C10,SUM(INDIRECT(ADDRESS(C9+1,17,,,"Paste cell here")):INDIRECT(ADDRESS(C10+1,17,,,"Paste cell here"))),SUM('Paste cell here'!Q2:INDIRECT(ADDRESS(C10+1,17,,,"Paste cell here")))+SUM(INDIRECT(ADDRESS(C9+1,17,,,"Paste cell here")):'Paste cell here'!Q366))) | E44: =IF(ISTEXT(D9),"",IF(D9<D10,SUM(INDIRECT(ADDRESS(D9+1,17,,,"Paste cell here")):INDIRECT(ADDRESS(D10+1,17,,,"Paste cell here"))),SUM('Paste cell here'!R2:INDIRECT(ADDRESS(D10+1,17,,,"Paste cell here")))+SUM(INDIRECT(ADDRESS(D9+1,17,,,"Paste cell here")):'Paste cell here'!R366))) | F44: =IF(ISTEXT(E9),"",IF(E9<E10,SUM(INDIRECT(ADDRESS(E9+1,17,,,"Paste cell here")):INDIRECT(ADDRESS(E10+1,17,,,"Paste cell here"))),SUM('Paste cell here'!S2:INDIRECT(ADDRESS(E10+1,17,,,"Paste cell here")))+SUM(INDIRECT(ADDRESS(E9+1,17,,,"Paste cell here")):'Paste cell here'!S366))) | G44: =IF(ISTEXT(F9),"",IF(F9<F10,SUM(INDIRECT(ADDRESS(F9+1,17,,,"Paste cell here")):INDIRECT(ADDRESS(F10+1,17,,,"Paste cell here"))),SUM('Paste cell here'!T2:INDIRECT(ADDRESS(F10+1,17,,,"Paste cell here")))+SUM(INDIRECT(ADDRESS(F9+1,17,,,"Paste cell here")):'Paste cell here'!T366)))
...

Sheet Paste cell here
A1: Giulian_day | B1: rain_mm | C1: Tmax | D1: Tmin | E1: et0 | F1: kcb | G1: lai | H1: pday | I1: irrig_mm | J1: eff_rain_mm | K1: GrossAv_water_mm | L1: NetAv_water_mm | M1: interception_mm | N1: runoff_mm | O1: infiltration_mm | P1: eva_pot_mm | Q1: eva_mm | R1: trasp_pot1_mm | S1: trasp_act1_mm | T1: perc1_mm | U1: theta1_mm | V1: ponding_mm | W1: rise_mm | X1: trasp_pot2_mm | Y1: trasp_act2_mm | Z1: ks | AA1: thickness_II_m | AB1: wat_table_depth_under_root_m | AC1: capflux_mm | AD1: perc2_mm | AE1: theta2_mm | AF1: theta_old_mm | AG1: rawbig | AH1: rawinf | AI1: wat_table_depth_m | AJ1: distr_irr_mm | AK1: priv_well_irr_mm | AL1: espperc1 | AM1: espperc2 | AN1: irr_loss_mm | AO1: RF_e | AP1: RF_t | AQ1: r_stress | AR1: h_r | AS1: h_wp | AT1: h_fc | AU1: h_sat | AV1: h_maxpond
A2: 1 | B2: 16.783061 | C2: 2.7460747 | D2: 0.46124941 | E2: 0.23609479 | F2: 0 | G2: 0 | H2: 0.7 | I2: 0 | J2: 16.783061 | K2: 16.783061 | L2: 12.778205 | M2: 0 | N2: 4.0048554 | O2: 12.778206 | P2: 0.28331376 | Q2: 0.28331376 | R2: 0 | S2: 0 | T2: 3.1797259 | U2: 32.236066 | V2: 0 | W2: 0 | X2: 0 | Y2: 0 | Z2: 1 | AA2: 0.9 | AB2: 99 | AC2: 0 | AD2: 0.21086889 | AE2: 180.26526 | AF2: 177.2964 | AG2: 130.20818 | AH2: 95.61276 | AI2: 100 | AJ2: 0 | AK2: 0 | AL2: 1 | AM2: 1 | AN2: 0 | AO2: 0 | AP2: 1 | AQ2: 0 | AR2: 58.7952 | AS2: 81.198 | AT2: 177.2964 | AU2: 389.8692 | AV2: 0
A3: 2 | B3: 20.887131 | C3: 4.0688511 | D3: 1.4973203 | E3: 0.25406543 | F3: 0 | G3: 0 | H3: 0.68866745 | I3: 0 | J3: 20.887131 | K3: 20.887131 | L3: 13.802792 | M3: 0 | N3: 7.0843396 | O3: 13.802792 | P3: 0.30487852 | Q3: 0.30487852 | R3: 0 | S3: 0 | T3: 12.10418 | U3: 33.6298 | V3: 0 | W3: 0 | X3: 0 | Y3: 0 | Z3: 1 | AA3: 0.9 | AB3: 99 | AC3: 0 | AD3: 0.36486832 | AE3: 192.00457 | AF3: 180.26526 | AG3: 130.97051 | AH3: 96.15728 | AI3: 100 | AJ3: 0 | AK3: 0 | AL3: 1 | AM3: 1 | AN3: 0 | AO3: 0 | AP3: 1 | AQ3: 0 | AR3: 58.7952 | AS3: 81.198 | AT3: 177.2964 | AU3: 389.8692 | AV3: 0
A4: 3 | B4: 4.5169535 | C4: 8.1612494 | D4: 2.0300588 | E4: 0.21547654 | F4: 0 | G4: 0 | H4: 0.68780485 | I4: 0 | J4: 4.5169535 | K4: 4.5169535 | L4: 4.5142544 | M4: 0 | N4: 0.0027 | O4: 4.5142546 | P4: 0.25857186 | Q4: 0.25857186 | R4: 0 | S4: 0 | T4: 7.1943807 | U4: 30.691102 | V4: 0 | W4: 0 | X4: 0 | Y4: 0 | Z4: 1 | AA4: 0.9 | AB4: 99 | AC4: 0 | AD4: 0.67606668 | AE4: 198.52288 | AF4: 192.00457 | AG4: 131.02854 | AH4: 96.198727 | AI4: 100 | AJ4: 0 | AK4: 0 | AL4: 1 | AM4: 1 | AN4: 0 | AO4: 0 | AP4: 1 | AQ4: 0 | AR4: 58.7952 | AS4: 81.198 | AT4: 177.2964 | AU4: 389.8692 | AV4: 0
A5: 4 | B5: 6.3450449 | C5: 6.7460747 | D5: 4.3895113 | E5: 0.23386219 | F5: 0 | G5: 0 | H5: 0.68965712 | I5: 0 | J5: 6.3450449 | K5: 6.3450449 | L5: 6.1806438 | M5: 0 | N5: 0.16440108 | O5: 6.180644 | P5: 0.28063463 | Q5: 0.28063463 | R5: 0 | S5: 0 | T5: 5.5225037 | U5: 31.068607 | V5: 0 | W5: 0 | X5: 0 | Y5: 0 | Z5: 1 | AA5: 0.9 | AB5: 99 | AC5: 0 | AD5: 0.90791604 | AE5: 203.13747 | AF5: 198.52288 | AG5: 130.90394 | AH5: 96.109727 | AI5: 100 | AJ5: 0 | AK5: 0 | AL5: 1 | AM5: 1 | AN5: 0 | AO5: 0 | AP5: 1 | AQ5: 0 | AR5: 58.7952 | AS5: 81.198 | AT5: 177.2964 | AU5: 389.8692 | AV5: 0
A6: 5 | B6: 8.6108977 | C6: 6.9 | D6: 2.9820195 | E6: 0.33052826 | F6: 0 | G6: 0 | H6: 0.68877461 | I6: 0 | J6: 8.6108977 | K6: 8.6108977 | L6: 7.9041036 | M6: 0 | N6: 0.7067941 | O6: 7.9041038 | P6: 0.39663392 | Q6: 0.39663392 | R6: 0 | S6: 0 | T6: 6.7961811 | U6: 31.779896 | V6: 0 | W6: 0 | X6: 0 | Y6: 0 | Z6: 1 | AA6: 0.9 | AB6: 99 | AC6: 0 | AD6: 1.2173893 | AE6: 208.71626 | AF6: 203.13747 | AG6: 130.9633 | AH6: 96.152131 | AI6: 100 | AJ6: 0 | AK6: 0 | AL6: 1 | AM6: 1 | AN6: 0 | AO6: 0 | AP6: 1 | AQ6: 0 | AR6: 58.7952 | AS6: 81.198 | AT6: 177.2964 | AU6: 389.8692 | AV6: 0
A7: 6 | B7: 0.76821911 | C7: 5.8026797 | D7: 2.4179805 | E7: 0.27605688 | F7: 0 | G7: 0 | H7: 0.68413464 | I7: 0 | J7: 0.76821911 | K7: 0.76821911 | L7: 0.76821911 | M7: 0 | N7: 0 | O7: 0.76821913 | P7: 0.33126827 | Q7: 0.33126827 | R7: 0 | S7: 0 | T7: 3.8009933 | U7: 28.415854 | V7: 0 | W7: 0 | X7: 0 | Y7: 0 | Z7: 1 | AA7: 0.9 | AB7: 99 | AC7: 0 | AD7: 1.5496757 | AE7: 210.96758 | AF7: 208.71626 | AG7: 131.27543 | AH7: 96.375078 | AI7: 100 | AJ7: 0 | AK7: 0 | AL7: 1 | AM7: 1 | AN7: 0 | AO7: 0 | AP7: 1 | AQ7: 0 | AR7: 58.7952 | AS7: 81.198 | AT7: 177.2964 | AU7: 389.8692 | AV7: 0
A8: 7 | B8: 0 | C8: 7.5311489 | D8: 1.8820195 | E8: 0.34334283 | F8: 0 | G8: 0 | H8: 0.68674926 | I8: 0 | J8: 0 | K8: 0 | L8: 0 | M8: 0 | N8: 0 | O8: 0 | P8: 0.4120114 | Q8: 0.4120114 | R8: 0 | S8: 0 | T8: 1.4983006 | U8: 26.505542 | V8: 0 | W8: 0 | X8: 0 | Y8: 0 | Z8: 1 | AA8: 0.9 | AB8: 99 | AC8: 0 | AD8: 1.6163221 | AE8: 210.84956 | AF8: 210.96758 | AG8: 131.09955 | AH8: 96.249447 | AI8: 100 | AJ8: 0 | AK8: 0 | AL8: 1 | AM8: 1 | AN8: 0 | AO8: 0 | AP8: 1 | AQ8: 0 | AR8: 58.7952 | AS8: 81.198 | AT8: 177.2964 | AU8: 389.8692 | AV8: 0
A9: 8 | B9: 1.8182941 | C9: 6.9926759 | D9: -2.756605 | E9: 0.15304997 | F9: 0 | G9: 0 | H9: 0.68351954 | I9: 0 | J9: 1.8182941 | K9: 1.8182941 | L9: 1.8182941 | M9: 0 | N9: 0 | O9: 1.8182941 | P9: 0.18365997 | Q9: 0.18365997 | R9: 0 | S9: 0 | T9: 1.1476926 | U9: 26.992483 | V9: 0 | W9: 0 | X9: 0 | Y9: 0 | Z9: 1 | AA9: 0.9 | AB9: 99 | AC9: 0 | AD9: 1.5817011 | AE9: 210.41555 | AF9: 210.84956 | AG9: 131.31681 | AH9: 96.404633 | AI9: 100 | AJ9: 0 | AK9: 0 | AL9: 1 | AM9: 1 | AN9: 0 | AO9: 0 | AP9: 1 | AQ9: 0 | AR9: 58.7952 | AS9: 81.198 | AT9: 177.2964 | AU9: 389.8692 | AV9: 0
A10: 9 | B10: 0 | C10: 5.1073241 | D10: -2.3745439 | E10: 0.32686016 | F10: 0 | G10: 0 | H10: 0.6926536 | I10: 0 | J10: 0 | K10: 0 | L10: 0 | M10: 0 | N10: 0 | O10: 0 | P10: 0.39223221 | Q10: 0.39223221 | R10: 0 | S10: 0 | T10: 0.94780999 | U10: 25.652441 | V10: 0 | W10: 0 | X10: 0 | Y10: 0 | Z10: 1 | AA10: 0.9 | AB10: 99 | AC10: 0 | AD10: 1.5431979 | AE10: 209.82016 | AF10: 210.41555 | AG10: 130.70237 | AH10: 95.965749 | AI10: 100 | AJ10: 0 | AK10: 0 | AL10: 1 | AM10: 1 | AN10: 0 | AO10: 0 | AP10: 1 | AQ10: 0 | AR10: 58.7952 | AS10: 81.198 | AT10: 177.2964 | AU10: 389.8692 | AV10: 0
A11: 10 | B11: 0 | C11: 4.7926759 | D11: -3.3640552 | E11: 0.38540601 | F11: 0 | G11: 0 | H11: 0.68431071 | I11: 0 | J11: 0 | K11: 0 | L11: 0 | M11: 0 | N11: 0 | O11: 0 | P11: 0.46248722 | Q11: 0.46248722 | R11: 0 | S11: 0 | T11: 0.57089935 | U11: 24.619055 | V11: 0 | W11: 0 | X11: 0 | Y11: 0 | Z11: 1 | AA11: 0.9 | AB11: 99 | AC11: 0 | AD11: 1.4786345 | AE11: 208.91243 | AF11: 209.82016 | AG11: 131.26359 | AH11: 96.366618 | AI11: 100 | AJ11: 0 | AK11: 0 | AL11: 1 | AM11: 1 | AN11: 0 | AO11: 0 | AP11: 1 | AQ11: 0 | AR11: 58.7952 | AS11: 81.198 | AT11: 177.2964 | AU11: 389.8692 | AV11: 0
A12: 11 | B12: 0 | C12: 5.4 | D12: -5.3847154 | E12: 0.21565158 | F12: 0 | G12: 0 | H12: 0.68150051 | I12: 0 | J12: 0 | K12: 0 | L12: 0 | M12: 0 | N12: 0 | O12: 0 | P12: 0.2587819 | Q12: 0.2587819 | R12: 0 | S12: 0 | T12: 0.38888244 | U12: 23.97139 | V12: 0 | W12: 0 | X12: 0 | Y12: 0 | Z12: 1 | AA12: 0.9 | AB12: 99 | AC12: 0 | AD12: 1.400736 | AE12: 207.90057 | AF12: 208.91243 | AG12: 131.45262 | AH12: 96.501646 | AI12: 100 | AJ12: 0 | AK12: 0 | AL12: 1 | AM12: 1 | AN12: 0 | AO12: 0 | AP12: 1 | AQ12: 0 | AR12: 58.7952 | AS12: 81.198 | AT12: 177.2964 | AU12: 389.8692 | AV12: 0
A13: 12 | B13: 0 | C13: 5.4 | D13: -5.1206602 | E13: 0.31862094 | F13: 0 | G13: 0 | H13: 0.68964872 | I13: 0 | J13: 0 | K13: 0 | L13: 0 | M13: 0 | N13: 0 | O13: 0 | P13: 0.38234513 | Q13: 0.38234513 | R13: 0 | S13: 0 | T13: 0.28550773 | U13: 23.303537 | V13: 0 | W13: 0 | X13: 0 | Y13: 0 | Z13: 1 | AA13: 0.9 | AB13: 99 | AC13: 0 | AD13: 1.3225829 | AE13: 206.8635 | AF13: 207.90057 | AG13: 130.9045 | AH13: 96.110131 | AI13: 100 | AJ13: 0 | AK13: 0 | AL13: 1 | AM13: 1 | AN13: 0 | AO13: 0 | AP13: 1 | AQ13: 0 | AR13: 58.7952 | AS13: 81.198 | AT13: 177.2964 | AU13: 389.8692 | AV13: 0
... A308: 307 | B308: 23.646188 | C308: 12.766735 | D308: 7.2254561 | E308: 0.45489117 | F308: 0 | G308: 0 | H308: 0.67193705 | I308: 0 | J308: 23.646188 | K308: 23.646188 | L308: 14.413218 | M308: 0 | N308: 9.2329708 | O308: 14.413218 | P308: 0.54586942 | Q308: 0.54586942 | R308: 0 | S308: 0 | T308: 10.213248 | U308: 33.681307 | V308: 0 | W308: 0 | X308: 0 | Y308: 0 | Z308: 1 | AA308: 0.2 | AB308: 99.7 | AC308: 0 | AD308: 5.8966869 | AE308: 54.829882 | AF308: 50.513321 | AG308: 29.354655 | AH308: 21.546925 | AI308: 100 | AJ308: 0 | AK308: 0 | AL308: 1 | AM308: 1 | AN308: 0 | AO308: 0 | AP308: 1 | AQ308: 0 | AR308: 13.0656 | AS308: 18.044 | AT308: 39.3992 | AU308: 86.6376 | AV308: 0

Sheet Paste cellparameters here
A1: input files
A2: WPadj | B2: 0.325
A3: HI | B3: 0.45
A4: KyT | B4: 1.25
A5: Ky1 | B5: 0.4
A6: Ky2 | B6: 0.9
A7: Ky3 | B7: 1.5
A8: Ky4 | B8: 0.5
A9: Tcrit | B9: 32
A10: Tlim | B10: 40
A11: Kcbmin | B11: 0
A12: Kcbini | B12: 0.15
A13: Kcbmax | B13: 1.046
... A18: irandom | B18: -5

Sheet Paste cellinfo here
A1: input files
A2: Domain | B2: 1
A3: Slope | B3: 0.001
A4: Soil use | B4: 13
A5: Irrigation subdistrict | B5: null
A6: Irrigation method | B6: 1
A7: Method efficiency | B7: null
A8: Conveyance efficiency | B8: null
A9: Hydrologic soil group | B9: 2
A10: Hydrologic condition | B10: 1
A11: ThetaI_sat | B11: 0.518024
A12: ThetaI_fc | B12: 0.229209
A13: ThetaI_wp | B13: 0.0831
A14: ThetaI_r | B14: 0.048
A15: ThetaII_sat | B15: 0.433188
A16: ThetaII_fc | B16: 0.196996
A17: ThetaII_wp | B17: 0.0902
A18: ThetaII_r | B18: 0.0653
A19: ksat_I | B19: 4.76184
A20: ksat_II | B20: 4.411071
... A25: Simulation year | B25: 2021
A26: CapFluxParam_a3 | B26: null
A27: CapFluxParam_a4 | B27: null
A28: CapFluxParam_b1 | B28: null
A29: CapFluxParam_b2 | B29: null
A30: CapFluxParam_b3 | B30: null
A31: CapFluxParam_b4 | B31: null
A32: Water depth | B32: null
A33: am_perc1 | B33: 6.8762412
A34: am_perc2 | B34: 6.9109861
A35: bm_perc1 | B35: 0.69331559
A36: bm_perc2 | B36: 0.68115485
A37: Meteorological Station nr 1 | B37: 297.48484
A38: Meteorological Station nr 2 | B38: 50.151525
A39: Meteorological Station nr 3 | B39: 306.13962
A40: Meteorological Station nr 4 | B40: 51.126069
A41: Meteorological Station nr 5 | B41: 89.097949

Sheet Rootzone balance
A1: DOY | B1: Date | C1: Rainfall [mm] | D1: Irrigation [mm] | E1: p [-] | F1: Thickness lyr 1 [m] | G1: Thickness lyr 2 [m] | H1: wcontent lyr 1 [mm] | I1: wcontent lyr 2 [mm] | J1: wcontent used for trigger [mm] | K1: Trigger threshold [mm] | L1: is trying to irrigate | M1: wcont at FC lyr1 [mm] | N1: wcont at WP lyr1 [mm] | O1: TAW lyr1 [mm] | P1: wcont at FC lyr2 [mm] | Q1: wcont at WP lyr2 [mm] | R1: TAW lyr2 [mm]
A2: 1 | B2: =DATE(Sintesi!$C$4-1,12,31)+A2 | C2: ='Paste cell here'!B2 | D2: ='Paste cell here'!I2 | E2: ='Paste cell here'!H2 | F2: =Sintesi!$C$5 | G2: ='Paste cell here'!AA2 | H2: ='Paste cell here'!U2 | I2: ='Paste cell here'!AE2 | K2: ='Paste cell here'!AG2 | M2: =(Sintesi!$C$29*F2*1000) | N2: =Sintesi!$C$30*F2*1000 | O2: =M2-N2 | P2: =Sintesi!$C$33*G2*1000 | Q2: =Sintesi!$C$34*G2*1000 | R2: =P2-Q2
A3: 2 | B3: =DATE(Sintesi!$C$4-1,12,31)+A3 | C3: ='Paste cell here'!B3 | D3: ='Paste cell here'!I3 | E3: ='Paste cell here'!H3 | F3: =Sintesi!$C$5 | G3: ='Paste cell here'!AA3 | H3: ='Paste cell here'!U3 | I3: ='Paste cell here'!AE3 | J3: ='Paste cell here'!U2+'Paste cell here'!AF3 | K3: ='Paste cell here'!AG3 | L3: =IF(J3<K3,"YES","NO") | M3: =(Sintesi!$C$29*F3*1000) | N3: =Sintesi!$C$30*F3*1000 | O3: =M3-N3 | P3: =Sintesi!$C$33*G3*1000 | Q3: =Sintesi!$C$34*G3*1000 | R3: =P3-Q3
A4: 3 | B4: =DATE(Sintesi!$C$4-1,12,31)+A4 | C4: ='Paste cell here'!B4 | D4: ='Paste cell here'!I4 | E4: ='Paste cell here'!H4 | F4: =Sintesi!$C$5 | G4: ='Paste cell here'!AA4 | H4: ='Paste cell here'!U4 | I4: ='Paste cell here'!AE4 | J4: ='Paste cell here'!U3+'Paste cell here'!AF4 | K4: ='Paste cell here'!AG4 | L4: =IF(J4<K4,"YES","NO") | M4: =(Sintesi!$C$29*F4*1000) | N4: =Sintesi!$C$30*F4*1000 | O4: =M4-N4 | P4: =Sintesi!$C$33*G4*1000 | Q4: =Sintesi!$C$34*G4*1000 | R4: =P4-Q4
A5: 4 | B5: =DATE(Sintesi!$C$4-1,12,31)+A5 | C5: ='Paste cell here'!B5 | D5: ='Paste cell here'!I5 | E5: ='Paste cell here'!H5 | F5: =Sintesi!$C$5 | G5: ='Paste cell here'!AA5 | H5: ='Paste cell here'!U5 | I5: ='Paste cell here'!AE5 | J5: ='Paste cell here'!U4+'Paste cell here'!AF5 | K5: ='Paste cell here'!AG5 | L5: =IF(J5<K5,"YES","NO") | M5: =(Sintesi!$C$29*F5*1000) | N5: =Sintesi!$C$30*F5*1000 | O5: =M5-N5 | P5: =Sintesi!$C$33*G5*1000 | Q5: =Sintesi!$C$34*G5*1000 | R5: =P5-Q5
A6: 5 | B6: =DATE(Sintesi!$C$4-1,12,31)+A6 | C6: ='Paste cell here'!B6 | D6: ='Paste cell here'!I6 | E6: ='Paste cell here'!H6 | F6: =Sintesi!$C$5 | G6: ='Paste cell here'!AA6 | H6: ='Paste cell here'!U6 | I6: ='Paste cell here'!AE6 | J6: ='Paste cell here'!U5+'Paste cell here'!AF6 | K6: ='Paste cell here'!AG6 | L6: =IF(J6<K6,"YES","NO") | M6: =(Sintesi!$C$29*F6*1000) | N6: =Sintesi!$C$30*F6*1000 | O6: =M6-N6 | P6: =Sintesi!$C$33*G6*1000 | Q6: =Sintesi!$C$34*G6*1000 | R6: =P6-Q6
A7: 6 | B7: =DATE(Sintesi!$C$4-1,12,31)+A7 | C7: ='Paste cell here'!B7 | D7: ='Paste cell here'!I7 | E7: ='Paste cell here'!H7 | F7: =Sintesi!$C$5 | G7: ='Paste cell here'!AA7 | H7: ='Paste cell here'!U7 | I7: ='Paste cell here'!AE7 | J7: ='Paste cell here'!U6+'Paste cell here'!AF7 | K7: ='Paste cell here'!AG7 | L7: =IF(J7<K7,"YES","NO") | M7: =(Sintesi!$C$29*F7*1000) | N7: =Sintesi!$C$30*F7*1000 | O7: =M7-N7 | P7: =Sintesi!$C$33*G7*1000 | Q7: =Sintesi!$C$34*G7*1000 | R7: =P7-Q7
A8: 7 | B8: =DATE(Sintesi!$C$4-1,12,31)+A8 | C8: ='Paste cell here'!B8 | D8: ='Paste cell here'!I8 | E8: ='Paste cell here'!H8 | F8: =Sintesi!$C$5 | G8: ='Paste cell here'!AA8 | H8: ='Paste cell here'!U8 | I8: ='Paste cell here'!AE8 | J8: ='Paste cell here'!U7+'Paste cell here'!AF8 | K8: ='Paste cell here'!AG8 | L8: =IF(J8<K8,"YES","NO") | M8: =(Sintesi!$C$29*F8*1000) | N8: =Sintesi!$C$30*F8*1000 | O8: =M8-N8 | P8: =Sintesi!$C$33*G8*1000 | Q8: =Sintesi!$C$34*G8*1000 | R8: =P8-Q8
A9: 8 | B9: =DATE(Sintesi!$C$4-1,12,31)+A9 | C9: ='Paste cell here'!B9 | D9: ='Paste cell here'!I9 | E9: ='Paste cell here'!H9 | F9: =Sintesi!$C$5 | G9: ='Paste cell here'!AA9 | H9: ='Paste cell here'!U9 | I9: ='Paste cell here'!AE9 | J9: ='Paste cell here'!U8+'Paste cell here'!AF9 | K9: ='Paste cell here'!AG9 | L9: =IF(J9<K9,"YES","NO") | M9: =(Sintesi!$C$29*F9*1000) | N9: =Sintesi!$C$30*F9*1000 | O9: =M9-N9 | P9: =Sintesi!$C$33*G9*1000 | Q9: =Sintesi!$C$34*G9*1000 | R9: =P9-Q9
A10: 9 | B10: =DATE(Sintesi!$C$4-1,12,31)+A10 | C10: ='Paste cell here'!B10 | D10: ='Paste cell here'!I10 | E10: ='Paste cell here'!H10 | F10: =Sintesi!$C$5 | G10: ='Paste cell here'!AA10 | H10: ='Paste cell here'!U10 | I10: ='Paste cell here'!AE10 | J10: ='Paste cell here'!U9+'Paste cell here'!AF10 | K10: ='Paste cell here'!AG10 | L10: =IF(J10<K10,"YES","NO") | M10: =(Sintesi!$C$29*F10*1000) | N10: =Sintesi!$C$30*F10*1000 | O10: =M10-N10 | P10: =Sintesi!$C$33*G10*1000 | Q10: =Sintesi!$C$34*G10*1000 | R10: =P10-Q10
A11: 10 | B11: =DATE(Sintesi!$C$4-1,12,31)+A11 | C11: ='Paste cell here'!B11 | D11: ='Paste cell here'!I11 | E11: ='Paste cell here'!H11 | F11: =Sintesi!$C$5 | G11: ='Paste cell here'!AA11 | H11: ='Paste cell here'!U11 | I11: ='Paste cell here'!AE11 | J11: ='Paste cell here'!U10+'Paste cell here'!AF11 | K11: ='Paste cell here'!AG11 | L11: =IF(J11<K11,"YES","NO") | M11: =(Sintesi!$C$29*F11*1000) | N11: =Sintesi!$C$30*F11*1000 | O11: =M11-N11 | P11: =Sintesi!$C$33*G11*1000 | Q11: =Sintesi!$C$34*G11*1000 | R11: =P11-Q11
A12: 11 | B12: =DATE(Sintesi!$C$4-1,12,31)+A12 | C12: ='Paste cell here'!B12 | D12: ='Paste cell here'!I12 | E12: ='Paste cell here'!H12 | F12: =Sintesi!$C$5 | G12: ='Paste cell here'!AA12 | H12: ='Paste cell here'!U12 | I12: ='Paste cell here'!AE12 | J12: ='Paste cell here'!U11+'Paste cell here'!AF12 | K12: ='Paste cell here'!AG12 | L12: =IF(J12<K12,"YES","NO") | M12: =(Sintesi!$C$29*F12*1000) | N12: =Sintesi!$C$30*F12*1000 | O12: =M12-N12 | P12: =Sintesi!$C$33*G12*1000 | Q12: =Sintesi!$C$34*G12*1000 | R12: =P12-Q12
A13: 12 | B13: =DATE(Sintesi!$C$4-1,12,31)+A13 | C13: ='Paste cell here'!B13 | D13: ='Paste cell here'!I13 | E13: ='Paste cell here'!H13 | F13: =Sintesi!$C$5 | G13: ='Paste cell here'!AA13 | H13: ='Paste cell here'!U13 | I13: ='Paste cell here'!AE13 | J13: ='Paste cell here'!U12+'Paste cell here'!AF13 | K13: ='Paste cell here'!AG13 | L13: =IF(J13<K13,"YES","NO") | M13: =(Sintesi!$C$29*F13*1000) | N13: =Sintesi!$C$30*F13*1000 | O13: =M13-N13 | P13: =Sintesi!$C$33*G13*1000 | Q13: =Sintesi!$C$34*G13*1000 | R13: =P13-Q13
A14: 13 | B14: =DATE(Sintesi!$C$4-1,12,31)+A14 | C14: ='Paste cell here'!B14 | D14: ='Paste cell here'!I14 | E14: ='Paste cell here'!H14 | F14: =Sintesi!$C$5 | G14: ='Paste cell here'!AA14 | H14: ='Paste cell here'!U14 | I14: ='Paste cell here'!AE14 | J14: ='Paste cell here'!U13+'Paste cell here'!AF14 | K14: ='Paste cell here'!AG14 | L14: =IF(J14<K14,"YES","NO") | M14: =(Sintesi!$C$29*F14*1000) | N14: =Sintesi!$C$30*F14*1000 | O14: =M14-N14 | P14: =Sintesi!$C$33*G14*1000 | Q14: =Sintesi!$C$34*G14*1000 | R14: =P14-Q14
... A366: 365 | B366: =DATE(Sintesi!$C$4-1,12,31)+A366 | C366: ='Paste cell here'!B366 | D366: ='Paste cell here'!I366 | E366: ='Paste cell here'!H366 | F366: =Sintesi!$C$5 | G366: ='Paste cell here'!AA366 | H366: ='Paste cell here'!U366 | I366: ='Paste cell here'!AE366 | J366: ='Paste cell here'!U365+'Paste cell here'!AF366 | K366: ='Paste cell here'!AG366 | L366: =IF(J366<K366,"YES","NO") | M366: =(Sintesi!$C$29*F366*1000) | N366: =Sintesi!$C$30*F366*1000 | O366: =M366-N366 | P366: =Sintesi!$C$33*G366*1000 | Q366: =Sintesi!$C$34*G366*1000 | R366: =P366-Q366

Sheet Verifica produttività
A1: Giorno giuliano | B1: Data | C1: Id coltura | D1: Fase | E1: Kcb | F1: Tmax [°C] | G1: Tmin [°C] | H1: ET0 [mm] | I1: Traspirazione potenziale [mm] | J1: Traspirazione effettiva [mm] | K1: Tp/ET0 | L1: Tday [°C] | M1: fHSd | O1: Mese | P1: Tmax_time | Q1: Tmin_time
A2: ='Paste cell here'!A2 | B2: =DATE(Sintesi!$C$4-1,12,31)+A2 | C2: {=_xlfn.IFNA(MATCH(1,((_xlfn.ANCHORARRAY(Sintesi!$C$9)>_xlfn.ANCHORARRAY(Sintesi!$C$10))*(A2>=_xlfn.ANCHORARRAY(Sintesi!$C$9))+(_xlfn.ANCHORARRAY(Sintesi!$C$9)>_xlfn.ANCHORARRAY(Sintesi!$C$10))*(A2<=_xlfn.ANCHORARRAY(Sintesi!$C$10))+(_xlfn.ANCHORARRAY(Sintesi!$C$9)<_xlfn.ANCHORARRAY(Sintesi!$C$10))*(A2>=_xlfn.ANCHORARRAY(Sintesi!$C$9))*(A2<=_xlfn.ANCHORARRAY(Sintesi!$C$10)))*(_xlfn.ANCHORARRAY(Sintesi!$C$15)>=0)+(_xlfn.ANCHORARRAY(Sintesi!$C$15)<0),0),0)} | D2: {=IF(ISBLANK($E3),IF(ISNUMBER($E1),IF($C2>0,IF(($E2=INDEX(_xlfn.ANCHORARRAY(Sintesi!$C$14),1,$C2))*(INDEX(_xlfn.ANCHORARRAY(Sintesi!$C$15),1,$C2)>0),0,IF(($E2=INDEX(_xlfn.ANCHORARRAY(Sintesi!$C$14),1,$C2))*(INDEX(_xlfn.ANCHORARRAY(Sintesi!$C$15),1,$C2)<0)+($E2>=$E1)*($E2<=INDEX($E:$E,MATCH(TRUE,INDEX((ISNUMBER($E:$E)),0),0)))*($E2>INDEX(_xlfn.ANCHORARRAY(Sintesi!$C$14),1,$C2))*($E2<=INDEX(_xlfn.ANCHORARRAY(Sintesi!$C$15),1,$C2))*(INDEX(_xlfn.ANCHORARRAY(Sintesi!$C$15),1,$C2)>0),1,IF(($E2>=$E1)*($E2<=INDEX($E:$E,MATCH(TRUE,INDEX((ISNUMBER($E:$E)),0),0)))*($E2>INDEX(_xlfn.ANCHORARRAY(Sintesi!$C$14),1,$C2))*($E2<INDEX(_xlfn.ANCHORARRAY(Sintesi!$C$16),1,$C2))*(INDEX(_xlfn.ANCHORARRAY(Sintesi!$C$15),1,$C2)<0)+($E2>=$E1)*($E2<=INDEX($E:$E,MATCH(TRUE,INDEX((ISNUMBER($E:$E)),0),0)))*($E2>INDEX(_xlfn.ANCHORARRAY(Sintesi!$C$15),1,$C2))*($E2<INDEX(_xlfn.ANCHORARRAY(Sintesi!$C$16),1,$C2))*(INDEX(_xlfn.ANCHORARRAY(Sintesi!$C$15),1,$C2)>0),2,IF($E2=(INDEX(_xlfn.ANCHORARRAY(Sintesi!$C$16),1,$C2)),3,4)))),0),IF($C2>0,IF(($E2=INDEX(_xlfn.ANCHORARRAY(Sintesi!$C$14),1,$C2))*(INDEX(_xlfn.ANCHORARRAY(Sintesi!$C$15),1,$C2)>0),0,IF(($E2=INDEX(_xlfn.ANCHORARRAY(Sintesi!$C$14),1,$C2))*(INDEX(_xlfn.ANCHORARRAY(Sintesi!$C$15),1,$C2)<0)+($E2>=LOOKUP(2,1/($E:$E<>""),$E:$E))*($E2<=INDEX($E:$E,MATCH(TRUE,INDEX((ISNUMBER($E:$E)),0),0)))*($E2>INDEX(_xlfn.ANCHORARRAY(Sintesi!$C$14),1,$C2))*($E2<=INDEX(_xlfn.ANCHORARRAY(Sintesi!$C$15),1,$C2))*(INDEX(_xlfn.ANCHORARRAY(Sintesi!$C$15),1,$C2)>0),1,IF(($E2>=LOOKUP(2,1/($E:$E<>""),$E:$E))*($E2<=INDEX($E:$E,MATCH(TRUE,INDEX((ISNUMBER($E:$E)),0),0)))*($E2>INDEX(_xlfn.ANCHORARRAY(Sintesi!$C$14),1,$C2))*($E2<INDEX(_xlfn.ANCHORARRAY(Sintesi!$C$16),1,$C2))*(INDEX(_xlfn.ANCHORARRAY(Sintesi!$C$15),1,$C2)<0)+($E2>=LOOKUP(2,1/($E:$E<>""),$E:$E))*($E2<=INDEX($E:$E,MATCH(TRUE,INDEX((ISNUMBER($E:$E)),0),0)))*($E2>INDEX(_xlfn.ANCHORARRAY(Sintesi!$C$15),1,$C2))*($E2<INDEX(_xlfn.ANCHORARRAY(Sintesi!$C$16),1,$C2))*(INDEX(_xlfn.ANCHORARRAY(Sintesi!$C$15),1,$C2)>0),2,IF($E2=(INDEX(_xlfn.ANCHORARRAY(Sintesi!$C$16),1,$C2)),3,4)))),0)),IF(ISNUMBER($E1),IF($C2>0,IF(($E2=INDEX(_xlfn.ANCHORARRAY(Sintesi!$C$14),1,$C2))*(INDEX(_xlfn.ANCHORARRAY(Sintesi!$C$15),1,$C2)>0),0,IF(($E2=INDEX(_xlfn.ANCHORARRAY(Sintesi!$C$14),1,$C2))*(INDEX(_xlfn.ANCHORARRAY(Sintesi!$C$15),1,$C2)<0)+($E2>=$E1)*($E2<=$E3)*($E2>INDEX(_xlfn.ANCHORARRAY(Sintesi!$C$14),1,$C2))*($E2<=INDEX(_xlfn.ANCHORARRAY(Sintesi!$C$15),1,$C2))*(INDEX(_xlfn.ANCHORARRAY(Sintesi!$C$15),1,$C2)>0),1,IF(($E2>=$E1)*($E2<=$E3)*($E2>INDEX(_xlfn.ANCHORARRAY(Sintesi!$C$14),1,$C2))*($E2<INDEX(_xlfn.ANCHORARRAY(Sintesi!$C$16),1,$C2))*(INDEX(_xlfn.ANCHORARRAY(Sintesi!$C$15),1,$C2)<0)+($E2>=$E1)*($E2<=$E3)*($E2>INDEX(_xlfn.ANCHORARRAY(Sintesi!$C$15),1,$C2))*($E2<INDEX(_xlfn.ANCHORARRAY(Sintesi!$C$16),1,$C2))*(INDEX(_xlfn.ANCHORARRAY(Sintesi!$C$15),1,$C2)>0),2,IF($E2=(INDEX(_xlfn.ANCHORARRAY(Sintesi!$C$16),1,$C2)),3,4)))),0),IF($C2>0,IF(($E2=INDEX(_xlfn.ANCHORARRAY(Sintesi!$C$14),1,$C2))*(INDEX(_xlfn.ANCHORARRAY(Sintesi!$C$15),1,$C2)>0),0,IF(($E2=INDEX(_xlfn.ANCHORARRAY(Sintesi!$C$14),1,$C2))*(INDEX(_xlfn.ANCHORARRAY(Sintesi!$C$15),1,$C2)<0)+($E2>=LOOKUP(2,1/($E:$E<>""),$E:$E))*($E2<=$E3)*($E2>INDEX(_xlfn.ANCHORARRAY(Sintesi!$C$14),1,$C2))*($E2<=INDEX(_xlfn.ANCHORARRAY(Sintesi!$C$15),1,$C2))*(INDEX(_xlfn.ANCHORARRAY(Sintesi!$C$15),1,$C2)>0),1,IF(($E2>=LOOKUP(2,1/($E:$E<>""),$E:$E))*($E2<=$E3)*($E2>INDEX(_xlfn.ANCHORARRAY(Sintesi!$C$14),1,$C2))*($E2<INDEX(_xlfn.ANCHORARRAY(Sintesi!$C$16),1,$C2))*(INDEX(_xlfn.ANCHORARRAY(Sintesi!$C$15),1,$C2)<0)+($E2>=LOOKUP(2,1/($E:$E<>""),$E:$E))*($E2<=$E3)*($E2>INDEX(_xlfn.ANCHORARRAY(Sintesi!$C$15),1,$C2))*($E2<INDEX(_xlfn.ANCHORARRAY(Sintesi!$C$16),1,$C2))*(INDEX(_xlfn.ANCHORARRAY(Sintesi!$C$15),1,$C2)>0),2,IF($E2=(INDEX(_xlfn.ANCHORARRAY(Sintesi!$C$16),1,$C2)),3,4)))),0)))} | E2: ='Paste cell here'!F2 | F2: ='Paste cell here'!C2 | G2: ='Paste cell here'!D2 | H2: ='Paste cell here'!E2 | I2: ='Paste cell here'!X2 | J2: ='Paste cell here'!Y2+'Paste cell here'!S2 | K2: =I2/H2 | L2: =AVERAGE(($F2+$G2)/2-($F2-$G2)/2*COS(PI()*(8-VLOOKUP(MONTH(B2),$O$1:$Q$13,3))/(VLOOKUP(MONTH(B2),$O$1:$Q$13,2)-VLOOKUP(MONTH(B2),$O$1:$Q$13,3))),($F2+$G2)/2-($F2-$G2)/2*COS(PI()*(9-VLOOKUP(MONTH(B2),$O$1:$Q$13,3))/(VLOOKUP(MONTH(B2),$O$1:$Q$13,2)-VLOOKUP(MONTH(B2),$O$1:$Q$13,3))),($F2+$G2)/2-($F2-$G2)/2*COS(PI()*(10-VLOOKUP(MONTH(B2),$O$1:$Q$13,3))/(VLOOKUP(MONTH(B2),$O$1:$Q$13,2)-VLOOKUP(MONTH(B2),$O$1:$Q$13,3))),($F2+$G2)/2-($F2-$G2)/2*COS(PI()*(11-VLOOKUP(MONTH(B2),$O$1:$Q$13,3))/(VLOOKUP(MONTH(B2),$O$1:$Q$13,2)-VLOOKUP(MONTH(B2),$O$1:$Q$13,3))),($F2+$G2)/2-($F2-$G2)/2*COS(PI()*(12-VLOOKUP(MONTH(B2),$O$1:$Q$13,3))/(VLOOKUP(MONTH(B2),$O$1:$Q$13,2)-VLOOKUP(MONTH(B2),$O$1:$Q$13,3))),($F2+$G2)/2-($F2-$G2)/2*COS(PI()*(13-VLOOKUP(MONTH(B2),$O$1:$Q$13,3))/(VLOOKUP(MONTH(B2),$O$1:$Q$13,2)-VLOOKUP(MONTH(B2),$O$1:$Q$13,3))),($F2+$G2)/2-($F2-$G2)/2*COS(PI()*(14-VLOOKUP(MONTH(B2),$O$1:$Q$13,3))/(VLOOKUP(MONTH(B2),$O$1:$Q$13,2)-VLOOKUP(MONTH(B2),$O$1:$Q$13,3)))) | M2: {=IF(AND(A2>=_xlfn.IFNA(INDEX(IF(ROUND(0.45*_xlfn.ANCHORARRAY(Sintesi!$C$11),0)+_xlfn.ANCHORARRAY(Sintesi!$C$9)>365,ROUND(0.45*_xlfn.ANCHORARRAY(Sintesi!$C$11),0)+_xlfn.ANCHORARRAY(Sintesi!$C$9)-365,ROUND(0.45*_xlfn.ANCHORARRAY(Sintesi!$C$11),0)+_xlfn.ANCHORARRAY(Sintesi!$C$9)),1,MATCH(1,(_xlfn.ANCHORARRAY(Sintesi!$C$9)>_xlfn.ANCHORARRAY(Sintesi!$C$10))*(A2>=_xlfn.ANCHORARRAY(Sintesi!$C$9))+(_xlfn.ANCHORARRAY(Sintesi!$C$9)>_xlfn.ANCHORARRAY(Sintesi!$C$10))*(A2<=_xlfn.ANCHORARRAY(Sintesi!$C$10))+(_xlfn.ANCHORARRAY(Sintesi!$C$9)<_xlfn.ANCHORARRAY(Sintesi!$C$10))*(A2>=_xlfn.ANCHORARRAY(Sintesi!$C$9))*(A2<=_xlfn.ANCHORARRAY(Sintesi!$C$10)),0)),0),A2<_xlfn.IFNA(INDEX(IF(ROUND(0.75*_xlfn.ANCHORARRAY(Sintesi!$C$11),0)+_xlfn.ANCHORARRAY(Sintesi!$C$9)>365,ROUND(0.75*_xlfn.ANCHORARRAY(Sintesi!$C$11),0)+_xlfn.ANCHORARRAY(Sintesi!$C$9)-365,ROUND(0.75*_xlfn.ANCHORARRAY(Sintesi!$C$11),0)+_xlfn.ANCHORARRAY(Sintesi!$C$9)),1,MATCH(1,(_xlfn.ANCHORARRAY(Sintesi!$C$9)>_xlfn.ANCHORARRAY(Sintesi!$C$10))*(A3>=_xlfn.ANCHORARRAY(Sintesi!$C$9))+(_xlfn.ANCHORARRAY(Sintesi!$C$9)>_xlfn.ANCHORARRAY(Sintesi!$C$10))*(A3<=_xlfn.ANCHORARRAY(Sintesi!$C$10))+(_xlfn.ANCHORARRAY(Sintesi!$C$9)<_xlfn.ANCHORARRAY(Sintesi!$C$10))*(A3>=_xlfn.ANCHORARRAY(Sintesi!$C$9))*(A3<=_xlfn.ANCHORARRAY(Sintesi!$C$10)),0)),0)),IF(L2<_xlfn.IFNA(INDEX(_xlfn.ANCHORARRAY(Sintesi!$C$17),1,MATCH(1,(_xlfn.ANCHORARRAY(Sintesi!$C$9)>_xlfn.ANCHORARRAY(Sintesi!$C$10))*(A1>=_xlfn.ANCHORARRAY(Sintesi!$C$9))+(_xlfn.ANCHORARRAY(Sintesi!$C$9)>_xlfn.ANCHORARRAY(Sintesi!$C$10))*(A1<=_xlfn.ANCHORARRAY(Sintesi!$C$10))+(_xlfn.ANCHORARRAY(Sintesi!$C$9)<_xlfn.ANCHORARRAY(Sintesi!$C$10))*(A1>=_xlfn.ANCHORARRAY(Sintesi!$C$9))*(A1<=_xlfn.ANCHORARRAY(Sintesi!$C$10)),0)),0),1,IF(L2>=_xlfn.IFNA(INDEX(_xlfn.ANCHORARRAY(Sintesi!$C$18),1,MATCH(1,(_xlfn.ANCHORARRAY(Sintesi!$C$9)>_xlfn.ANCHORARRAY(Sintesi!$C$10))*(A1>=_xlfn.ANCHORARRAY(Sintesi!$C$9))+(_xlfn.ANCHORARRAY(Sintesi!$C$9)>_xlfn.ANCHORARRAY(Sintesi!$C$10))*(A1<=_xlfn.ANCHORARRAY(Sintesi!$C$10))+(_xlfn.ANCHORARRAY(Sintesi!$C$9)<_xlfn.ANCHORARRAY(Sintesi!$C$10))*(A1>=_xlfn.ANCHORARRAY(Sintesi!$C$9))*(A1<=_xlfn.ANCHORARRAY(Sintesi!$C$10)),0)),0),0,1-(L2-_xlfn.IFNA(INDEX(_xlfn.ANCHORARRAY(Sintesi!$C$17),1,MATCH(1,(_xlfn.ANCHORARRAY(Sintesi!$C$9)>_xlfn.ANCHORARRAY(Sintesi!$C$10))*(A1>=_xlfn.ANCHORARRAY(Sintesi!$C$9))+(_xlfn.ANCHORARRAY(Sintesi!$C$9)>_xlfn.ANCHORARRAY(Sintesi!$C$10))*(A1<=_xlfn.ANCHORARRAY(Sintesi!$C$10))+(_xlfn.ANCHORARRAY(Sintesi!$C$9)<_xlfn.ANCHORARRAY(Sintesi!$C$10))*(A1>=_xlfn.ANCHORARRAY(Sintesi!$C$9))*(A1<=_xlfn.ANCHORARRAY(Sintesi!$C$10)),0)),0))/(_xlfn.IFNA(INDEX(_xlfn.ANCHORARRAY(Sintesi!$C$18),1,MATCH(1,(_xlfn.ANCHORARRAY(Sintesi!$C$9)>_xlfn.ANCHORARRAY(Sintesi!$C$10))*(A1>=_xlfn.ANCHORARRAY(Sintesi!$C$9))+(_xlfn.ANCHORARRAY(Sintesi!$C$9)>_xlfn.ANCHORARRAY(Sintesi!$C$10))*(A1<=_xlfn.ANCHORARRAY(Sintesi!$C$10))+(_xlfn.ANCHORARRAY(Sintesi!$C$9)<_xlfn.ANCHORARRAY(Sintesi!$C$10))*(A1>=_xlfn.ANCHORARRAY(Sintesi!$C$9))*(A1<=_xlfn.ANCHORARRAY(Sintesi!$C$10)),0)),0)-_xlfn.IFNA(INDEX(_xlfn.ANCHORARRAY(Sintesi!$C$17),1,MATCH(1,(_xlfn.ANCHORARRAY(Sintesi!$C$9)>_xlfn.ANCHORARRAY(Sintesi!$C$10))*(A1>=_xlfn.ANCHORARRAY(Sintesi!$C$9))+(_xlfn.ANCHORARRAY(Sintesi!$C$9)>_xlfn.ANCHORARRAY(Sintesi!$C$10))*(A1<=_xlfn.ANCHORARRAY(Sintesi!$C$10))+(_xlfn.ANCHORARRAY(Sintesi!$C$9)<_xlfn.ANCHORARRAY(Sintesi!$C$10))*(A1>=_xlfn.ANCHORARRAY(Sintesi!$C$9))*(A1<=_xlfn.ANCHORARRAY(Sintesi!$C$10)),0)),0)))),0)} | O2: 1 | P2: 14 | Q2: 6
A3: ='Paste cell here'!A3 | B3: =DATE(Sintesi!$C$4-1,12,31)+A3 | C3: {=_xlfn.IFNA(MATCH(1,((_xlfn.ANCHORARRAY(Sintesi!$C$9)>_xlfn.ANCHORARRAY(Sintesi!$C$10))*(A3>=_xlfn.ANCHORARRAY(Sintesi!$C$9))+(_xlfn.ANCHORARRAY(Sintesi!$C$9)>_xlfn.ANCHORARRAY(Sintesi!$C$10))*(A3<=_xlfn.ANCHORARRAY(Sintesi!$C$10))+(_xlfn.ANCHORARRAY(Sintesi!$C$9)<_xlfn.ANCHORARRAY(Sintesi!$C$10))*(A3>=_xlfn.ANCHORARRAY(Sintesi!$C$9))*(A3<=_xlfn.ANCHORARRAY(Sintesi!$C$10)))*(_xlfn.ANCHORARRAY(Sintesi!$C$15)>=0)+(_xlfn.ANCHORARRAY(Sintesi!$C$15)<0),0),0)} | D3: {=IF(ISBLANK($E4),IF(ISNUMBER($E2),IF($C3>0,IF(($E3=INDEX(_xlfn.ANCHORARRAY(Sintesi!$C$14),1,$C3))*(INDEX(_xlfn.ANCHORARRAY(Sintesi!$C$15),1,$C3)>0),0,IF(($E3=INDEX(_xlfn.ANCHORARRAY(Sintesi!$C$14),1,$C3))*(INDEX(_xlfn.ANCHORARRAY(Sintesi!$C$15),1,$C3)<0)+($E3>=$E2)*($E3<=INDEX($E:$E,MATCH(TRUE,INDEX((ISNUMBER($E:$E)),0),0)))*($E3>INDEX(_xlfn.ANCHORARRAY(Sintesi!$C$14),1,$C3))*($E3<=INDEX(_xlfn.ANCHORARRAY(Sintesi!$C$15),1,$C3))*(INDEX(_xlfn.ANCHORARRAY(Sintesi!$C$15),1,$C3)>0),1,IF(($E3>=$E2)*($E3<=INDEX($E:$E,MATCH(TRUE,INDEX((ISNUMBER($E:$E)),0),0)))*($E3>INDEX(_xlfn.ANCHORARRAY(Sintesi!$C$14),1,$C3))*($E3<INDEX(_xlfn.ANCHORARRAY(Sintesi!$C$16),1,$C3))*(INDEX(_xlfn.ANCHORARRAY(Sintesi!$C$15),1,$C3)<0)+($E3>=$E2)*($E3<=INDEX($E:$E,MATCH(TRUE,INDEX((ISNUMBER($E:$E)),0),0)))*($E3>INDEX(_xlfn.ANCHORARRAY(Sintesi!$C$15),1,$C3))*($E3<INDEX(_xlfn.ANCHORARRAY(Sintesi!$C$16),1,$C3))*(INDEX(_xlfn.ANCHORARRAY(Sintesi!$C$15),1,$C3)>0),2,IF($E3=(INDEX(_xlfn.ANCHORARRAY(Sintesi!$C$16),1,$C3)),3,4)))),0),IF($C3>0,IF(($E3=INDEX(_xlfn.ANCHORARRAY(Sintesi!$C$14),1,$C3))*(INDEX(_xlfn.ANCHORARRAY(Sintesi!$C$15),1,$C3)>0),0,IF(($E3=INDEX(_xlfn.ANCHORARRAY(Sintesi!$C$14),1,$C3))*(INDEX(_xlfn.ANCHORARRAY(Sintesi!$C$15),1,$C3)<0)+($E3>=LOOKUP(2,1/($E:$E<>""),$E:$E))*($E3<=INDEX($E:$E,MATCH(TRUE,INDEX((ISNUMBER($E:$E)),0),0)))*($E3>INDEX(_xlfn.ANCHORARRAY(Sintesi!$C$14),1,$C3))*($E3<=INDEX(_xlfn.ANCHORARRAY(Sintesi!$C$15),1,$C3))*(INDEX(_xlfn.ANCHORARRAY(Sintesi!$C$15),1,$C3)>0),1,IF(($E3>=LOOKUP(2,1/($E:$E<>""),$E:$E))*($E3<=INDEX($E:$E,MATCH(TRUE,INDEX((ISNUMBER($E:$E)),0),0)))*($E3>INDEX(_xlfn.ANCHORARRAY(Sintesi!$C$14),1,$C3))*($E3<INDEX(_xlfn.ANCHORARRAY(Sintesi!$C$16),1,$C3))*(INDEX(_xlfn.ANCHORARRAY(Sintesi!$C$15),1,$C3)<0)+($E3>=LOOKUP(2,1/($E:$E<>""),$E:$E))*($E3<=INDEX($E:$E,MATCH(TRUE,INDEX((ISNUMBER($E:$E)),0),0)))*($E3>INDEX(_xlfn.ANCHORARRAY(Sintesi!$C$15),1,$C3))*($E3<INDEX(_xlfn.ANCHORARRAY(Sintesi!$C$16),1,$C3))*(INDEX(_xlfn.ANCHORARRAY(Sintesi!$C$15),1,$C3)>0),2,IF($E3=(INDEX(_xlfn.ANCHORARRAY(Sintesi!$C$16),1,$C3)),3,4)))),0)),IF(ISNUMBER($E2),IF($C3>0,IF(($E3=INDEX(_xlfn.ANCHORARRAY(Sintesi!$C$14),1,$C3))*(INDEX(_xlfn.ANCHORARRAY(Sintesi!$C$15),1,$C3)>0),0,IF(($E3=INDEX(_xlfn.ANCHORARRAY(Sintesi!$C$14),1,$C3))*(INDEX(_xlfn.ANCHORARRAY(Sintesi!$C$15),1,$C3)<0)+($E3>=$E2)*($E3<=$E4)*($E3>INDEX(_xlfn.ANCHORARRAY(Sintesi!$C$14),1,$C3))*($E3<=INDEX(_xlfn.ANCHORARRAY(Sintesi!$C$15),1,$C3))*(INDEX(_xlfn.ANCHORARRAY(Sintesi!$C$15),1,$C3)>0),1,IF(($E3>=$E2)*($E3<=$E4)*($E3>INDEX(_xlfn.ANCHORARRAY(Sintesi!$C$14),1,$C3))*($E3<INDEX(_xlfn.ANCHORARRAY(Sintesi!$C$16),1,$C3))*(INDEX(_xlfn.ANCHORARRAY(Sintesi!$C$15),1,$C3)<0)+($E3>=$E2)*($E3<=$E4)*($E3>INDEX(_xlfn.ANCHORARRAY(Sintesi!$C$15),1,$C3))*($E3<INDEX(_xlfn.ANCHORARRAY(Sintesi!$C$16),1,$C3))*(INDEX(_xlfn.ANCHORARRAY(Sintesi!$C$15),1,$C3)>0),2,IF($E3=(INDEX(_xlfn.ANCHORARRAY(Sintesi!$C$16),1,$C3)),3,4)))),0),IF($C3>0,IF(($E3=INDEX(_xlfn.ANCHORARRAY(Sintesi!$C$14),1,$C3))*(INDEX(_xlfn.ANCHORARRAY(Sintesi!$C$15),1,$C3)>0),0,IF(($E3=INDEX(_xlfn.ANCHORARRAY(Sintesi!$C$14),1,$C3))*(INDEX(_xlfn.ANCHORARRAY(Sintesi!$C$15),1,$C3)<0)+($E3>=LOOKUP(2,1/($E:$E<>""),$E:$E))*($E3<=$E4)*($E3>INDEX(_xlfn.ANCHORARRAY(Sintesi!$C$14),1,$C3))*($E3<=INDEX(_xlfn.ANCHORARRAY(Sintesi!$C$15),1,$C3))*(INDEX(_xlfn.ANCHORARRAY(Sintesi!$C$15),1,$C3)>0),1,IF(($E3>=LOOKUP(2,1/($E:$E<>""),$E:$E))*($E3<=$E4)*($E3>INDEX(_xlfn.ANCHORARRAY(Sintesi!$C$14),1,$C3))*($E3<INDEX(_xlfn.ANCHORARRAY(Sintesi!$C$16),1,$C3))*(INDEX(_xlfn.ANCHORARRAY(Sintesi!$C$15),1,$C3)<0)+($E3>=LOOKUP(2,1/($E:$E<>""),$E:$E))*($E3<=$E4)*($E3>INDEX(_xlfn.ANCHORARRAY(Sintesi!$C$15),1,$C3))*($E3<INDEX(_xlfn.ANCHORARRAY(Sintesi!$C$16),1,$C3))*(INDEX(_xlfn.ANCHORARRAY(Sintesi!$C$15),1,$C3)>0),2,IF($E3=(INDEX(_xlfn.ANCHORARRAY(Sintesi!$C$16),1,$C3)),3,4)))),0)))} | E3: ='Paste cell here'!F3 | F3: ='Paste cell here'!C3 | G3: ='Paste cell here'!D3 | H3: ='Paste cell here'!E3 | I3: ='Paste cell here'!X3 | J3: ='Paste cell here'!Y3+'Paste cell here'!S3 | K3: =I3/H3 | L3: =AVERAGE(($F3+$G3)/2-($F3-$G3)/2*COS(PI()*(8-VLOOKUP(MONTH(B3),$O$1:$Q$13,3))/(VLOOKUP(MONTH(B3),$O$1:$Q$13,2)-VLOOKUP(MONTH(B3),$O$1:$Q$13,3))),($F3+$G3)/2-($F3-$G3)/2*COS(PI()*(9-VLOOKUP(MONTH(B3),$O$1:$Q$13,3))/(VLOOKUP(MONTH(B3),$O$1:$Q$13,2)-VLOOKUP(MONTH(B3),$O$1:$Q$13,3))),($F3+$G3)/2-($F3-$G3)/2*COS(PI()*(10-VLOOKUP(MONTH(B3),$O$1:$Q$13,3))/(VLOOKUP(MONTH(B3),$O$1:$Q$13,2)-VLOOKUP(MONTH(B3),$O$1:$Q$13,3))),($F3+$G3)/2-($F3-$G3)/2*COS(PI()*(11-VLOOKUP(MONTH(B3),$O$1:$Q$13,3))/(VLOOKUP(MONTH(B3),$O$1:$Q$13,2)-VLOOKUP(MONTH(B3),$O$1:$Q$13,3))),($F3+$G3)/2-($F3-$G3)/2*COS(PI()*(12-VLOOKUP(MONTH(B3),$O$1:$Q$13,3))/(VLOOKUP(MONTH(B3),$O$1:$Q$13,2)-VLOOKUP(MONTH(B3),$O$1:$Q$13,3))),($F3+$G3)/2-($F3-$G3)/2*COS(PI()*(13-VLOOKUP(MONTH(B3),$O$1:$Q$13,3))/(VLOOKUP(MONTH(B3),$O$1:$Q$13,2)-VLOOKUP(MONTH(B3),$O$1:$Q$13,3))),($F3+$G3)/2-($F3-$G3)/2*COS(PI()*(14-VLOOKUP(MONTH(B3),$O$1:$Q$13,3))/(VLOOKUP(MONTH(B3),$O$1:$Q$13,2)-VLOOKUP(MONTH(B3),$O$1:$Q$13,3)))) | M3: {=IF(AND(A3>=_xlfn.IFNA(INDEX(IF(ROUND(0.45*_xlfn.ANCHORARRAY(Sintesi!$C$11),0)+_xlfn.ANCHORARRAY(Sintesi!$C$9)>365,ROUND(0.45*_xlfn.ANCHORARRAY(Sintesi!$C$11),0)+_xlfn.ANCHORARRAY(Sintesi!$C$9)-365,ROUND(0.45*_xlfn.ANCHORARRAY(Sintesi!$C$11),0)+_xlfn.ANCHORARRAY(Sintesi!$C$9)),1,MATCH(1,(_xlfn.ANCHORARRAY(Sintesi!$C$9)>_xlfn.ANCHORARRAY(Sintesi!$C$10))*(A3>=_xlfn.ANCHORARRAY(Sintesi!$C$9))+(_xlfn.ANCHORARRAY(Sintesi!$C$9)>_xlfn.ANCHORARRAY(Sintesi!$C$10))*(A3<=_xlfn.ANCHORARRAY(Sintesi!$C$10))+(_xlfn.ANCHORARRAY(Sintesi!$C$9)<_xlfn.ANCHORARRAY(Sintesi!$C$10))*(A3>=_xlfn.ANCHORARRAY(Sintesi!$C$9))*(A3<=_xlfn.ANCHORARRAY(Sintesi!$C$10)),0)),0),A3<_xlfn.IFNA(INDEX(IF(ROUND(0.75*_xlfn.ANCHORARRAY(Sintesi!$C$11),0)+_xlfn.ANCHORARRAY(Sintesi!$C$9)>365,ROUND(0.75*_xlfn.ANCHORARRAY(Sintesi!$C$11),0)+_xlfn.ANCHORARRAY(Sintesi!$C$9)-365,ROUND(0.75*_xlfn.ANCHORARRAY(Sintesi!$C$11),0)+_xlfn.ANCHORARRAY(Sintesi!$C$9)),1,MATCH(1,(_xlfn.ANCHORARRAY(Sintesi!$C$9)>_xlfn.ANCHORARRAY(Sintesi!$C$10))*(A4>=_xlfn.ANCHORARRAY(Sintesi!$C$9))+(_xlfn.ANCHORARRAY(Sintesi!$C$9)>_xlfn.ANCHORARRAY(Sintesi!$C$10))*(A4<=_xlfn.ANCHORARRAY(Sintesi!$C$10))+(_xlfn.ANCHORARRAY(Sintesi!$C$9)<_xlfn.ANCHORARRAY(Sintesi!$C$10))*(A4>=_xlfn.ANCHORARRAY(Sintesi!$C$9))*(A4<=_xlfn.ANCHORARRAY(Sintesi!$C$10)),0)),0)),IF(L3<_xlfn.IFNA(INDEX(_xlfn.ANCHORARRAY(Sintesi!$C$17),1,MATCH(1,(_xlfn.ANCHORARRAY(Sintesi!$C$9)>_xlfn.ANCHORARRAY(Sintesi!$C$10))*(A2>=_xlfn.ANCHORARRAY(Sintesi!$C$9))+(_xlfn.ANCHORARRAY(Sintesi!$C$9)>_xlfn.ANCHORARRAY(Sintesi!$C$10))*(A2<=_xlfn.ANCHORARRAY(Sintesi!$C$10))+(_xlfn.ANCHORARRAY(Sintesi!$C$9)<_xlfn.ANCHORARRAY(Sintesi!$C$10))*(A2>=_xlfn.ANCHORARRAY(Sintesi!$C$9))*(A2<=_xlfn.ANCHORARRAY(Sintesi!$C$10)),0)),0),1,IF(L3>=_xlfn.IFNA(INDEX(_xlfn.ANCHORARRAY(Sintesi!$C$18),1,MATCH(1,(_xlfn.ANCHORARRAY(Sintesi!$C$9)>_xlfn.ANCHORARRAY(Sintesi!$C$10))*(A2>=_xlfn.ANCHORARRAY(Sintesi!$C$9))+(_xlfn.ANCHORARRAY(Sintesi!$C$9)>_xlfn.ANCHORARRAY(Sintesi!$C$10))*(A2<=_xlfn.ANCHORARRAY(Sintesi!$C$10))+(_xlfn.ANCHORARRAY(Sintesi!$C$9)<_xlfn.ANCHORARRAY(Sintesi!$C$10))*(A2>=_xlfn.ANCHORARRAY(Sintesi!$C$9))*(A2<=_xlfn.ANCHORARRAY(Sintesi!$C$10)),0)),0),0,1-(L3-_xlfn.IFNA(INDEX(_xlfn.ANCHORARRAY(Sintesi!$C$17),1,MATCH(1,(_xlfn.ANCHORARRAY(Sintesi!$C$9)>_xlfn.ANCHORARRAY(Sintesi!$C$10))*(A2>=_xlfn.ANCHORARRAY(Sintesi!$C$9))+(_xlfn.ANCHORARRAY(Sintesi!$C$9)>_xlfn.ANCHORARRAY(Sintesi!$C$10))*(A2<=_xlfn.ANCHORARRAY(Sintesi!$C$10))+(_xlfn.ANCHORARRAY(Sintesi!$C$9)<_xlfn.ANCHORARRAY(Sintesi!$C$10))*(A2>=_xlfn.ANCHORARRAY(Sintesi!$C$9))*(A2<=_xlfn.ANCHORARRAY(Sintesi!$C$10)),0)),0))/(_xlfn.IFNA(INDEX(_xlfn.ANCHORARRAY(Sintesi!$C$18),1,MATCH(1,(_xlfn.ANCHORARRAY(Sintesi!$C$9)>_xlfn.ANCHORARRAY(Sintesi!$C$10))*(A2>=_xlfn.ANCHORARRAY(Sintesi!$C$9))+(_xlfn.ANCHORARRAY(Sintesi!$C$9)>_xlfn.ANCHORARRAY(Sintesi!$C$10))*(A2<=_xlfn.ANCHORARRAY(Sintesi!$C$10))+(_xlfn.ANCHORARRAY(Sintesi!$C$9)<_xlfn.ANCHORARRAY(Sintesi!$C$10))*(A2>=_xlfn.ANCHORARRAY(Sintesi!$C$9))*(A2<=_xlfn.ANCHORARRAY(Sintesi!$C$10)),0)),0)-_xlfn.IFNA(INDEX(_xlfn.ANCHORARRAY(Sintesi!$C$17),1,MATCH(1,(_xlfn.ANCHORARRAY(Sintesi!$C$9)>_xlfn.ANCHORARRAY(Sintesi!$C$10))*(A2>=_xlfn.ANCHORARRAY(Sintesi!$C$9))+(_xlfn.ANCHORARRAY(Sintesi!$C$9)>_xlfn.ANCHORARRAY(Sintesi!$C$10))*(A2<=_xlfn.ANCHORARRAY(Sintesi!$C$10))+(_xlfn.ANCHORARRAY(Sintesi!$C$9)<_xlfn.ANCHORARRAY(Sintesi!$C$10))*(A2>=_xlfn.ANCHORARRAY(Sintesi!$C$9))*(A2<=_xlfn.ANCHORARRAY(Sintesi!$C$10)),0)),0)))),0)} | O3: 2 | P3: 14 | Q3: 6
A4: ='Paste cell here'!A4 | B4: =DATE(Sintesi!$C$4-1,12,31)+A4 | C4: {=_xlfn.IFNA(MATCH(1,((_xlfn.ANCHORARRAY(Sintesi!$C$9)>_xlfn.ANCHORARRAY(Sintesi!$C$10))*(A4>=_xlfn.ANCHORARRAY(Sintesi!$C$9))+(_xlfn.ANCHORARRAY(Sintesi!$C$9)>_xlfn.ANCHORARRAY(Sintesi!$C$10))*(A4<=_xlfn.ANCHORARRAY(Sintesi!$C$10))+(_xlfn.ANCHORARRAY(Sintesi!$C$9)<_xlfn.ANCHORARRAY(Sintesi!$C$10))*(A4>=_xlfn.ANCHORARRAY(Sintesi!$C$9))*(A4<=_xlfn.ANCHORARRAY(Sintesi!$C$10)))*(_xlfn.ANCHORARRAY(Sintesi!$C$15)>=0)+(_xlfn.ANCHORARRAY(Sintesi!$C$15)<0),0),0)} | D4: {=IF(ISBLANK($E5),IF(ISNUMBER($E3),IF($C4>0,IF(($E4=INDEX(_xlfn.ANCHORARRAY(Sintesi!$C$14),1,$C4))*(INDEX(_xlfn.ANCHORARRAY(Sintesi!$C$15),1,$C4)>0),0,IF(($E4=INDEX(_xlfn.ANCHORARRAY(Sintesi!$C$14),1,$C4))*(INDEX(_xlfn.ANCHORARRAY(Sintesi!$C$15),1,$C4)<0)+($E4>=$E3)*($E4<=INDEX($E:$E,MATCH(TRUE,INDEX((ISNUMBER($E:$E)),0),0)))*($E4>INDEX(_xlfn.ANCHORARRAY(Sintesi!$C$14),1,$C4))*($E4<=INDEX(_xlfn.ANCHORARRAY(Sintesi!$C$15),1,$C4))*(INDEX(_xlfn.ANCHORARRAY(Sintesi!$C$15),1,$C4)>0),1,IF(($E4>=$E3)*($E4<=INDEX($E:$E,MATCH(TRUE,INDEX((ISNUMBER($E:$E)),0),0)))*($E4>INDEX(_xlfn.ANCHORARRAY(Sintesi!$C$14),1,$C4))*($E4<INDEX(_xlfn.ANCHORARRAY(Sintesi!$C$16),1,$C4))*(INDEX(_xlfn.ANCHORARRAY(Sintesi!$C$15),1,$C4)<0)+($E4>=$E3)*($E4<=INDEX($E:$E,MATCH(TRUE,INDEX((ISNUMBER($E:$E)),0),0)))*($E4>INDEX(_xlfn.ANCHORARRAY(Sintesi!$C$15),1,$C4))*($E4<INDEX(_xlfn.ANCHORARRAY(Sintesi!$C$16),1,$C4))*(INDEX(_xlfn.ANCHORARRAY(Sintesi!$C$15),1,$C4)>0),2,IF($E4=(INDEX(_xlfn.ANCHORARRAY(Sintesi!$C$16),1,$C4)),3,4)))),0),IF($C4>0,IF(($E4=INDEX(_xlfn.ANCHORARRAY(Sintesi!$C$14),1,$C4))*(INDEX(_xlfn.ANCHORARRAY(Sintesi!$C$15),1,$C4)>0),0,IF(($E4=INDEX(_xlfn.ANCHORARRAY(Sintesi!$C$14),1,$C4))*(INDEX(_xlfn.ANCHORARRAY(Sintesi!$C$15),1,$C4)<0)+($E4>=LOOKUP(2,1/($E:$E<>""),$E:$E))*($E4<=INDEX($E:$E,MATCH(TRUE,INDEX((ISNUMBER($E:$E)),0),0)))*($E4>INDEX(_xlfn.ANCHORARRAY(Sintesi!$C$14),1,$C4))*($E4<=INDEX(_xlfn.ANCHORARRAY(Sintesi!$C$15),1,$C4))*(INDEX(_xlfn.ANCHORARRAY(Sintesi!$C$15),1,$C4)>0),1,IF(($E4>=LOOKUP(2,1/($E:$E<>""),$E:$E))*($E4<=INDEX($E:$E,MATCH(TRUE,INDEX((ISNUMBER($E:$E)),0),0)))*($E4>INDEX(_xlfn.ANCHORARRAY(Sintesi!$C$14),1,$C4))*($E4<INDEX(_xlfn.ANCHORARRAY(Sintesi!$C$16),1,$C4))*(INDEX(_xlfn.ANCHORARRAY(Sintesi!$C$15),1,$C4)<0)+($E4>=LOOKUP(2,1/($E:$E<>""),$E:$E))*($E4<=INDEX($E:$E,MATCH(TRUE,INDEX((ISNUMBER($E:$E)),0),0)))*($E4>INDEX(_xlfn.ANCHORARRAY(Sintesi!$C$15),1,$C4))*($E4<INDEX(_xlfn.ANCHORARRAY(Sintesi!$C$16),1,$C4))*(INDEX(_xlfn.ANCHORARRAY(Sintesi!$C$15),1,$C4)>0),2,IF($E4=(INDEX(_xlfn.ANCHORARRAY(Sintesi!$C$16),1,$C4)),3,4)))),0)),IF(ISNUMBER($E3),IF($C4>0,IF(($E4=INDEX(_xlfn.ANCHORARRAY(Sintesi!$C$14),1,$C4))*(INDEX(_xlfn.ANCHORARRAY(Sintesi!$C$15),1,$C4)>0),0,IF(($E4=INDEX(_xlfn.ANCHORARRAY(Sintesi!$C$14),1,$C4))*(INDEX(_xlfn.ANCHORARRAY(Sintesi!$C$15),1,$C4)<0)+($E4>=$E3)*($E4<=$E5)*($E4>INDEX(_xlfn.ANCHORARRAY(Sintesi!$C$14),1,$C4))*($E4<=INDEX(_xlfn.ANCHORARRAY(Sintesi!$C$15),1,$C4))*(INDEX(_xlfn.ANCHORARRAY(Sintesi!$C$15),1,$C4)>0),1,IF(($E4>=$E3)*($E4<=$E5)*($E4>INDEX(_xlfn.ANCHORARRAY(Sintesi!$C$14),1,$C4))*($E4<INDEX(_xlfn.ANCHORARRAY(Sintesi!$C$16),1,$C4))*(INDEX(_xlfn.ANCHORARRAY(Sintesi!$C$15),1,$C4)<0)+($E4>=$E3)*($E4<=$E5)*($E4>INDEX(_xlfn.ANCHORARRAY(Sintesi!$C$15),1,$C4))*($E4<INDEX(_xlfn.ANCHORARRAY(Sintesi!$C$16),1,$C4))*(INDEX(_xlfn.ANCHORARRAY(Sintesi!$C$15),1,$C4)>0),2,IF($E4=(INDEX(_xlfn.ANCHORARRAY(Sintesi!$C$16),1,$C4)),3,4)))),0),IF($C4>0,IF(($E4=INDEX(_xlfn.ANCHORARRAY(Sintesi!$C$14),1,$C4))*(INDEX(_xlfn.ANCHORARRAY(Sintesi!$C$15),1,$C4)>0),0,IF(($E4=INDEX(_xlfn.ANCHORARRAY(Sintesi!$C$14),1,$C4))*(INDEX(_xlfn.ANCHORARRAY(Sintesi!$C$15),1,$C4)<0)+($E4>=LOOKUP(2,1/($E:$E<>""),$E:$E))*($E4<=$E5)*($E4>INDEX(_xlfn.ANCHORARRAY(Sintesi!$C$14),1,$C4))*($E4<=INDEX(_xlfn.ANCHORARRAY(Sintesi!$C$15),1,$C4))*(INDEX(_xlfn.ANCHORARRAY(Sintesi!$C$15),1,$C4)>0),1,IF(($E4>=LOOKUP(2,1/($E:$E<>""),$E:$E))*($E4<=$E5)*($E4>INDEX(_xlfn.ANCHORARRAY(Sintesi!$C$14),1,$C4))*($E4<INDEX(_xlfn.ANCHORARRAY(Sintesi!$C$16),1,$C4))*(INDEX(_xlfn.ANCHORARRAY(Sintesi!$C$15),1,$C4)<0)+($E4>=LOOKUP(2,1/($E:$E<>""),$E:$E))*($E4<=$E5)*($E4>INDEX(_xlfn.ANCHORARRAY(Sintesi!$C$15),1,$C4))*($E4<INDEX(_xlfn.ANCHORARRAY(Sintesi!$C$16),1,$C4))*(INDEX(_xlfn.ANCHORARRAY(Sintesi!$C$15),1,$C4)>0),2,IF($E4=(INDEX(_xlfn.ANCHORARRAY(Sintesi!$C$16),1,$C4)),3,4)))),0)))} | E4: ='Paste cell here'!F4 | F4: ='Paste cell here'!C4 | G4: ='Paste cell here'!D4 | H4: ='Paste cell here'!E4 | I4: ='Paste cell here'!X4 | J4: ='Paste cell here'!Y4+'Paste cell here'!S4 | K4: =I4/H4 | L4: =AVERAGE(($F4+$G4)/2-($F4-$G4)/2*COS(PI()*(8-VLOOKUP(MONTH(B4),$O$1:$Q$13,3))/(VLOOKUP(MONTH(B4),$O$1:$Q$13,2)-VLOOKUP(MONTH(B4),$O$1:$Q$13,3))),($F4+$G4)/2-($F4-$G4)/2*COS(PI()*(9-VLOOKUP(MONTH(B4),$O$1:$Q$13,3))/(VLOOKUP(MONTH(B4),$O$1:$Q$13,2)-VLOOKUP(MONTH(B4),$O$1:$Q$13,3))),($F4+$G4)/2-($F4-$G4)/2*COS(PI()*(10-VLOOKUP(MONTH(B4),$O$1:$Q$13,3))/(VLOOKUP(MONTH(B4),$O$1:$Q$13,2)-VLOOKUP(MONTH(B4),$O$1:$Q$13,3))),($F4+$G4)/2-($F4-$G4)/2*COS(PI()*(11-VLOOKUP(MONTH(B4),$O$1:$Q$13,3))/(VLOOKUP(MONTH(B4),$O$1:$Q$13,2)-VLOOKUP(MONTH(B4),$O$1:$Q$13,3))),($F4+$G4)/2-($F4-$G4)/2*COS(PI()*(12-VLOOKUP(MONTH(B4),$O$1:$Q$13,3))/(VLOOKUP(MONTH(B4),$O$1:$Q$13,2)-VLOOKUP(MONTH(B4),$O$1:$Q$13,3))),($F4+$G4)/2-($F4-$G4)/2*COS(PI()*(13-VLOOKUP(MONTH(B4),$O$1:$Q$13,3))/(VLOOKUP(MONTH(B4),$O$1:$Q$13,2)-VLOOKUP(MONTH(B4),$O$1:$Q$13,3))),($F4+$G4)/2-($F4-$G4)/2*COS(PI()*(14-VLOOKUP(MONTH(B4),$O$1:$Q$13,3))/(VLOOKUP(MONTH(B4),$O$1:$Q$13,2)-VLOOKUP(MONTH(B4),$O$1:$Q$13,3)))) | M4: {=IF(AND(A4>=_xlfn.IFNA(INDEX(IF(ROUND(0.45*_xlfn.ANCHORARRAY(Sintesi!$C$11),0)+_xlfn.ANCHORARRAY(Sintesi!$C$9)>365,ROUND(0.45*_xlfn.ANCHORARRAY(Sintesi!$C$11),0)+_xlfn.ANCHORARRAY(Sintesi!$C$9)-365,ROUND(0.45*_xlfn.ANCHORARRAY(Sintesi!$C$11),0)+_xlfn.ANCHORARRAY(Sintesi!$C$9)),1,MATCH(1,(_xlfn.ANCHORARRAY(Sintesi!$C$9)>_xlfn.ANCHORARRAY(Sintesi!$C$10))*(A4>=_xlfn.ANCHORARRAY(Sintesi!$C$9))+(_xlfn.ANCHORARRAY(Sintesi!$C$9)>_xlfn.ANCHORARRAY(Sintesi!$C$10))*(A4<=_xlfn.ANCHORARRAY(Sintesi!$C$10))+(_xlfn.ANCHORARRAY(Sintesi!$C$9)<_xlfn.ANCHORARRAY(Sintesi!$C$10))*(A4>=_xlfn.ANCHORARRAY(Sintesi!$C$9))*(A4<=_xlfn.ANCHORARRAY(Sintesi!$C$10)),0)),0),A4<_xlfn.IFNA(INDEX(IF(ROUND(0.75*_xlfn.ANCHORARRAY(Sintesi!$C$11),0)+_xlfn.ANCHORARRAY(Sintesi!$C$9)>365,ROUND(0.75*_xlfn.ANCHORARRAY(Sintesi!$C$11),0)+_xlfn.ANCHORARRAY(Sintesi!$C$9)-365,ROUND(0.75*_xlfn.ANCHORARRAY(Sintesi!$C$11),0)+_xlfn.ANCHORARRAY(Sintesi!$C$9)),1,MATCH(1,(_xlfn.ANCHORARRAY(Sintesi!$C$9)>_xlfn.ANCHORARRAY(Sintesi!$C$10))*(A5>=_xlfn.ANCHORARRAY(Sintesi!$C$9))+(_xlfn.ANCHORARRAY(Sintesi!$C$9)>_xlfn.ANCHORARRAY(Sintesi!$C$10))*(A5<=_xlfn.ANCHORARRAY(Sintesi!$C$10))+(_xlfn.ANCHORARRAY(Sintesi!$C$9)<_xlfn.ANCHORARRAY(Sintesi!$C$10))*(A5>=_xlfn.ANCHORARRAY(Sintesi!$C$9))*(A5<=_xlfn.ANCHORARRAY(Sintesi!$C$10)),0)),0)),IF(L4<_xlfn.IFNA(INDEX(_xlfn.ANCHORARRAY(Sintesi!$C$17),1,MATCH(1,(_xlfn.ANCHORARRAY(Sintesi!$C$9)>_xlfn.ANCHORARRAY(Sintesi!$C$10))*(A3>=_xlfn.ANCHORARRAY(Sintesi!$C$9))+(_xlfn.ANCHORARRAY(Sintesi!$C$9)>_xlfn.ANCHORARRAY(Sintesi!$C$10))*(A3<=_xlfn.ANCHORARRAY(Sintesi!$C$10))+(_xlfn.ANCHORARRAY(Sintesi!$C$9)<_xlfn.ANCHORARRAY(Sintesi!$C$10))*(A3>=_xlfn.ANCHORARRAY(Sintesi!$C$9))*(A3<=_xlfn.ANCHORARRAY(Sintesi!$C$10)),0)),0),1,IF(L4>=_xlfn.IFNA(INDEX(_xlfn.ANCHORARRAY(Sintesi!$C$18),1,MATCH(1,(_xlfn.ANCHORARRAY(Sintesi!$C$9)>_xlfn.ANCHORARRAY(Sintesi!$C$10))*(A3>=_xlfn.ANCHORARRAY(Sintesi!$C$9))+(_xlfn.ANCHORARRAY(Sintesi!$C$9)>_xlfn.ANCHORARRAY(Sintesi!$C$10))*(A3<=_xlfn.ANCHORARRAY(Sintesi!$C$10))+(_xlfn.ANCHORARRAY(Sintesi!$C$9)<_xlfn.ANCHORARRAY(Sintesi!$C$10))*(A3>=_xlfn.ANCHORARRAY(Sintesi!$C$9))*(A3<=_xlfn.ANCHORARRAY(Sintesi!$C$10)),0)),0),0,1-(L4-_xlfn.IFNA(INDEX(_xlfn.ANCHORARRAY(Sintesi!$C$17),1,MATCH(1,(_xlfn.ANCHORARRAY(Sintesi!$C$9)>_xlfn.ANCHORARRAY(Sintesi!$C$10))*(A3>=_xlfn.ANCHORARRAY(Sintesi!$C$9))+(_xlfn.ANCHORARRAY(Sintesi!$C$9)>_xlfn.ANCHORARRAY(Sintesi!$C$10))*(A3<=_xlfn.ANCHORARRAY(Sintesi!$C$10))+(_xlfn.ANCHORARRAY(Sintesi!$C$9)<_xlfn.ANCHORARRAY(Sintesi!$C$10))*(A3>=_xlfn.ANCHORARRAY(Sintesi!$C$9))*(A3<=_xlfn.ANCHORARRAY(Sintesi!$C$10)),0)),0))/(_xlfn.IFNA(INDEX(_xlfn.ANCHORARRAY(Sintesi!$C$18),1,MATCH(1,(_xlfn.ANCHORARRAY(Sintesi!$C$9)>_xlfn.ANCHORARRAY(Sintesi!$C$10))*(A3>=_xlfn.ANCHORARRAY(Sintesi!$C$9))+(_xlfn.ANCHORARRAY(Sintesi!$C$9)>_xlfn.ANCHORARRAY(Sintesi!$C$10))*(A3<=_xlfn.ANCHORARRAY(Sintesi!$C$10))+(_xlfn.ANCHORARRAY(Sintesi!$C$9)<_xlfn.ANCHORARRAY(Sintesi!$C$10))*(A3>=_xlfn.ANCHORARRAY(Sintesi!$C$9))*(A3<=_xlfn.ANCHORARRAY(Sintesi!$C$10)),0)),0)-_xlfn.IFNA(INDEX(_xlfn.ANCHORARRAY(Sintesi!$C$17),1,MATCH(1,(_xlfn.ANCHORARRAY(Sintesi!$C$9)>_xlfn.ANCHORARRAY(Sintesi!$C$10))*(A3>=_xlfn.ANCHORARRAY(Sintesi!$C$9))+(_xlfn.ANCHORARRAY(Sintesi!$C$9)>_xlfn.ANCHORARRAY(Sintesi!$C$10))*(A3<=_xlfn.ANCHORARRAY(Sintesi!$C$10))+(_xlfn.ANCHORARRAY(Sintesi!$C$9)<_xlfn.ANCHORARRAY(Sintesi!$C$10))*(A3>=_xlfn.ANCHORARRAY(Sintesi!$C$9))*(A3<=_xlfn.ANCHORARRAY(Sintesi!$C$10)),0)),0)))),0)} | O4: 3 | P4: 14 | Q4: 5
